Traceback (most recent call last):
  File "/usr/share/miniconda/envs/prospect/lib/python3.8/site-packages/jupyter_cache/executors/utils.py", line 51, in single_nb_execution
    executenb(
  File "/usr/share/miniconda/envs/prospect/lib/python3.8/site-packages/nbclient/client.py", line 1087, in execute
    return NotebookClient(nb=nb, resources=resources, km=km, **kwargs).execute()
  File "/usr/share/miniconda/envs/prospect/lib/python3.8/site-packages/nbclient/util.py", line 74, in wrapped
    return just_run(coro(*args, **kwargs))
  File "/usr/share/miniconda/envs/prospect/lib/python3.8/site-packages/nbclient/util.py", line 53, in just_run
    return loop.run_until_complete(coro)
  File "/usr/share/miniconda/envs/prospect/lib/python3.8/asyncio/base_events.py", line 616, in run_until_complete
    return future.result()
  File "/usr/share/miniconda/envs/prospect/lib/python3.8/site-packages/nbclient/client.py", line 540, in async_execute
    await self.async_execute_cell(
  File "/usr/share/miniconda/envs/prospect/lib/python3.8/site-packages/nbclient/client.py", line 832, in async_execute_cell
    self._check_raise_for_error(cell, exec_reply)
  File "/usr/share/miniconda/envs/prospect/lib/python3.8/site-packages/nbclient/client.py", line 740, in _check_raise_for_error
    raise CellExecutionError.from_cell_and_msg(cell, exec_reply['content'])
nbclient.exceptions.CellExecutionError: An error occurred while executing the following cell:
------------------
layer_from_list = prospect.Layer(
    name='demo_layer', 
    area=demo_area,
    assemblage_name='demo_assemblage',
    input_features=[ft1, ft2, ft3]
)
------------------

[0;31m---------------------------------------------------------------------------[0m
[0;31mTypeError[0m                                 Traceback (most recent call last)
[0;32m<ipython-input-3-a78fabcd8fd8>[0m in [0;36m<module>[0;34m[0m
[0;32m----> 1[0;31m layer_from_list = prospect.Layer(
[0m[1;32m      2[0m     [0mname[0m[0;34m=[0m[0;34m'demo_layer'[0m[0;34m,[0m[0;34m[0m[0;34m[0m[0m
[1;32m      3[0m     [0marea[0m[0;34m=[0m[0mdemo_area[0m[0;34m,[0m[0;34m[0m[0;34m[0m[0m
[1;32m      4[0m     [0massemblage_name[0m[0;34m=[0m[0;34m'demo_assemblage'[0m[0;34m,[0m[0;34m[0m[0;34m[0m[0m
[1;32m      5[0m     [0minput_features[0m[0;34m=[0m[0;34m[[0m[0mft1[0m[0;34m,[0m [0mft2[0m[0;34m,[0m [0mft3[0m[0;34m][0m[0;34m[0m[0;34m[0m[0m

[0;31mTypeError[0m: __init__() got an unexpected keyword argument 'assemblage_name'
TypeError: __init__() got an unexpected keyword argument 'assemblage_name'

