Traceback (most recent call last):
  File "/opt/hostedtoolcache/Python/3.8.7/x64/lib/python3.8/site-packages/jupyter_cache/executors/utils.py", line 51, in single_nb_execution
    executenb(
  File "/opt/hostedtoolcache/Python/3.8.7/x64/lib/python3.8/site-packages/nbclient/client.py", line 1087, in execute
    return NotebookClient(nb=nb, resources=resources, km=km, **kwargs).execute()
  File "/opt/hostedtoolcache/Python/3.8.7/x64/lib/python3.8/site-packages/nbclient/util.py", line 74, in wrapped
    return just_run(coro(*args, **kwargs))
  File "/opt/hostedtoolcache/Python/3.8.7/x64/lib/python3.8/site-packages/nbclient/util.py", line 53, in just_run
    return loop.run_until_complete(coro)
  File "/opt/hostedtoolcache/Python/3.8.7/x64/lib/python3.8/asyncio/base_events.py", line 616, in run_until_complete
    return future.result()
  File "/opt/hostedtoolcache/Python/3.8.7/x64/lib/python3.8/site-packages/nbclient/client.py", line 540, in async_execute
    await self.async_execute_cell(
  File "/opt/hostedtoolcache/Python/3.8.7/x64/lib/python3.8/site-packages/nbclient/client.py", line 832, in async_execute_cell
    self._check_raise_for_error(cell, exec_reply)
  File "/opt/hostedtoolcache/Python/3.8.7/x64/lib/python3.8/site-packages/nbclient/client.py", line 740, in _check_raise_for_error
    raise CellExecutionError.from_cell_and_msg(cell, exec_reply['content'])
nbclient.exceptions.CellExecutionError: An error occurred while executing the following cell:
------------------
from shapely.geometry import Point
import prospect
from scipy.stats import beta

pt1 = Point(10, 10)
ft1 = prospect.Feature(
    name="feature1", 
    layer_name="demo_layer", 
    shape=pt1,
    time_penalty=prospect.utils.truncnorm(mean=10, sd=7, lower=0, upper=50),
    ideal_obs_rate=beta(9, 1)
)

pt2 = Point(50, 50)
ft2 = prospect.Feature(
    name="feature2",
    layer_name="demo_layer", 
    shape=pt2,
    time_penalty=prospect.utils.truncnorm(mean=10, sd=7, lower=0, upper=50),
    ideal_obs_rate=beta(9, 1)
)

pt3 = Point(90, 90)
ft3 = prospect.Feature(
    name="feature3",
    layer_name="demo_layer",
    shape=pt3,
    time_penalty=prospect.utils.truncnorm(mean=10, sd=7, lower=0, upper=50),
    ideal_obs_rate=beta(9, 1)
)
------------------

[0;31m---------------------------------------------------------------------------[0m
[0;31mModuleNotFoundError[0m                       Traceback (most recent call last)
[0;32m<ipython-input-1-dfa76d3e9ca4>[0m in [0;36m<module>[0;34m[0m
[1;32m      1[0m [0;32mfrom[0m [0mshapely[0m[0;34m.[0m[0mgeometry[0m [0;32mimport[0m [0mPoint[0m[0;34m[0m[0;34m[0m[0m
[0;32m----> 2[0;31m [0;32mimport[0m [0mprospect[0m[0;34m[0m[0;34m[0m[0m
[0m[1;32m      3[0m [0;32mfrom[0m [0mscipy[0m[0;34m.[0m[0mstats[0m [0;32mimport[0m [0mbeta[0m[0;34m[0m[0;34m[0m[0m
[1;32m      4[0m [0;34m[0m[0m
[1;32m      5[0m [0mpt1[0m [0;34m=[0m [0mPoint[0m[0;34m([0m[0;36m10[0m[0;34m,[0m [0;36m10[0m[0;34m)[0m[0;34m[0m[0;34m[0m[0m

[0;31mModuleNotFoundError[0m: No module named 'prospect'
ModuleNotFoundError: No module named 'prospect'

