Traceback (most recent call last):
  File "/usr/share/miniconda/envs/prospect/lib/python3.8/site-packages/jupyter_cache/executors/utils.py", line 51, in single_nb_execution
    executenb(
  File "/usr/share/miniconda/envs/prospect/lib/python3.8/site-packages/nbclient/client.py", line 1112, in execute
    return NotebookClient(nb=nb, resources=resources, km=km, **kwargs).execute()
  File "/usr/share/miniconda/envs/prospect/lib/python3.8/site-packages/nbclient/util.py", line 74, in wrapped
    return just_run(coro(*args, **kwargs))
  File "/usr/share/miniconda/envs/prospect/lib/python3.8/site-packages/nbclient/util.py", line 53, in just_run
    return loop.run_until_complete(coro)
  File "/usr/share/miniconda/envs/prospect/lib/python3.8/asyncio/base_events.py", line 616, in run_until_complete
    return future.result()
  File "/usr/share/miniconda/envs/prospect/lib/python3.8/site-packages/nbclient/client.py", line 553, in async_execute
    await self.async_execute_cell(
  File "/usr/share/miniconda/envs/prospect/lib/python3.8/site-packages/nbclient/client.py", line 857, in async_execute_cell
    self._check_raise_for_error(cell, exec_reply)
  File "/usr/share/miniconda/envs/prospect/lib/python3.8/site-packages/nbclient/client.py", line 760, in _check_raise_for_error
    raise CellExecutionError.from_cell_and_msg(cell, exec_reply_content)
nbclient.exceptions.CellExecutionError: An error occurred while executing the following cell:
------------------
coverage_from_list = prospect.Coverage(name="demo_coverage", area=demo_area, surveyunit_list=[su1, su2, su3], orientation=None, spacing=None)
------------------

[0;31m---------------------------------------------------------------------------[0m
[0;31mTypeError[0m                                 Traceback (most recent call last)
[0;32m<ipython-input-5-7edd45b730ab>[0m in [0;36m<module>[0;34m[0m
[0;32m----> 1[0;31m [0mcoverage_from_list[0m [0;34m=[0m [0mprospect[0m[0;34m.[0m[0mCoverage[0m[0;34m([0m[0mname[0m[0;34m=[0m[0;34m"demo_coverage"[0m[0;34m,[0m [0marea[0m[0;34m=[0m[0mdemo_area[0m[0;34m,[0m [0msurveyunit_list[0m[0;34m=[0m[0;34m[[0m[0msu1[0m[0;34m,[0m [0msu2[0m[0;34m,[0m [0msu3[0m[0;34m][0m[0;34m,[0m [0morientation[0m[0;34m=[0m[0;32mNone[0m[0;34m,[0m [0mspacing[0m[0;34m=[0m[0;32mNone[0m[0;34m)[0m[0;34m[0m[0;34m[0m[0m
[0m
[0;31mTypeError[0m: __init__() got an unexpected keyword argument 'area'
TypeError: __init__() got an unexpected keyword argument 'area'

